Workbook

Sheet groupe
A1: ETU003344 | B1: Eddou

Sheet liste des taches
A1: Ligne | B1: Catégorie | C1: Module | D1: Page | E1: Description tâche | F1: Type | G1: Qui | H1: Estimation | I1: Temps passé | J1: Reste à faire | K1: Avancement
A2: 1 | B2: Analyse | C2: Etude | D2: Analyse du sujet | E2: Analyse | F2: ETU003344 | G2: 60 | H2: 60 | I2: =detail_avancement!B2 -> 60 | J2: =H2-I2 -> 0 | K2: =(I2/(I2+J2)) -> 1
A3: 2 | B3: Analyse | C3: GLPI | D3: Installation GLPI | E3: Intégration | F3: ETU003344 | G3: 60 | H3: 60 | I3: =detail_avancement!B3 -> 60 | J3: =H3-I3 -> 0 | K3: =(I3/(I3+J3)) -> 1
A4: 3 | B4: Analyse | C4: GLPI | D4: Configuration MySQL | E4: Intégration | F4: ETU003344 | G4: 60 | H4: 60 | I4: =detail_avancement!B4 -> 60 | J4: =H4-I4 -> 0 | K4: =(I4/(I4+J4)) -> 1
A5: 4 | B5: Analyse | C5: GLPI | D5: Création projet React | E5: Intégration | F5: ETU003344 | G5: 60 | H5: 60 | I5: =detail_avancement!B5 -> 60 | J5: =H5-I5 -> 0 | K5: =(I5/(I5+J5)) -> 1
A6: 5 | B6: Architecture | C6: Backend | D6: Création projet Express | E6: Intégration | F6: ETU003344 | G6: 60 | H6: 60 | I6: =detail_avancement!B6 -> 60 | J6: =H6-I6 -> 0 | K6: =(I6/(I6+J6)) -> 1
A7: 6 | B7: Architecture | C7: Backend | D7: Création base SQLite | E7: Intégration | F7: ETU003344 | G7: 60 | H7: 60 | I7: =detail_avancement!B7 -> 60 | J7: =H7-I7 -> 0 | K7: =(I7/(I7+J7)) -> 1
A8: 7 | B8: Architecture | C8: Frontend | D8: Table paramètres SQLite | E8: Métier | F8: ETU003344 | G8: 60 | H8: 60 | I8: =detail_avancement!B8 -> 60 | J8: =H8-I8 -> 0 | K8: =(I8/(I8+J8)) -> 1
A9: 8 | B9: Architecture | C9: Frontend | D9: Authentification Backoffice | E9: Intégration | F9: ETU003344 | G9: 60 | H9: 60 | I9: =detail_avancement!B9 -> 60 | J9: =H9-I9 -> 0 | K9: =(I9/(I9+J9)) -> 1
A10: 9 | B10: Backend | C10: SQLite | D10: Protection des routes | E10: Intégration | F10: ETU003344 | G10: 60 | H10: 60 | I10: =detail_avancement!B10 -> 60 | J10: =H10-I10 -> 0 | K10: =(I10/(I10+J10)) -> 1
A11: 10 | B11: Backend | C11: SQLite | D11: API Réinitialisation | E11: Métier | F11: ETU003344 | G11: 60 | H11: 60 | I11: =detail_avancement!B11 -> 60 | J11: =H11-I11 -> 0 | K11: =(I11/(I11+J11)) -> 1
A12: 11 | B12: Backend | C12: SQLite | D12: Interface Réinitialisation | E12: Affichage | F12: ETU003344 | G12: 60 | H12: 60 | I12: =detail_avancement!B12 -> 60 | J12: =H12-I12 -> 0 | K12: =(I12/(I12+J12)) -> 1
A13: 12 | B13: Backend | C13: SQLite | D13: Import CSV Equipements | E13: Intégration | F13: ETU003344 | G13: 60 | H13: 60 | I13: =detail_avancement!B13 -> 60 | J13: =H13-I13 -> 0 | K13: =(I13/(I13+J13)) -> 1
... A74: 73 | B74: Tests | C74: Import | D74: Test déplacement | E74: Validation workflow | F74: ETU003344 | G74: 60 | H74: 60 | I74: =detail_avancement!B74 -> 60 | J74: =H74-I74 -> 0 | K74: =(I74/(I74+J74)) -> 1

Sheet Recap
B1: Données
A2: Qui | B2: SUM of Estimation | C2: SUM of Temps passé | D2: SUM of Reste à faire
A3: ETU003344 | B3: 2150 | C3: 2060 | D3: 90
A4: (vide) | B4: 30 | C4: 0 | D4: 30
A5: Total Résultat | B5: 2180 | C5: 2060 | D5: 120
A12: Avancement | B12: =avancement!D2 -> 1

Sheet avancement
A1: estimation total | B1: temps passé total | C1: reste à faire total | D1: avancement | E1: dépassement
A2: =SUM('liste des taches'!H:H) -> 4380 | B2: =SUM('liste des taches'!I:I) -> 4380 | C2: =SUM('liste des taches'!J:J) -> 0 | D2: =(B2/(B2+C2)) -> 1 | E2: =((B2+C2)-A2)/A2 -> 0
C3: =C2/60 -> 0 | D3: heure

Sheet detail_avancement
A1: Ligne | B1: Total | C1: 46178 | D1: 46179 | E1: 46180 | F1: 46181 | G1: 46182 | H1: 46183 | I1: 46184
A2: 1 | B2: =SUM(C2:O2) -> 60 | C2: 60
A3: 2 | B3: =SUM(C3:O3) -> 60 | C3: 60
A4: 3 | B4: =SUM(C4:O4) -> 60 | C4: 60
A5: 4 | B5: =SUM(C5:O5) -> 60 | C5: 60
A6: 5 | B6: =SUM(C6:O6) -> 60 | C6: 60
A7: 6 | B7: =SUM(C7:O7) -> 60 | C7: 60
A8: 7 | B8: =SUM(C8:O8) -> 60 | C8: 60
A9: 8 | B9: =SUM(C9:O9) -> 60 | C9: 60
A10: 9 | B10: =SUM(C10:O10) -> 60 | C10: 60
A11: 10 | B11: =SUM(C11:O11) -> 60 | C11: 60
A12: 11 | B12: =SUM(C12:O12) -> 60 | C12: 60
A13: 12 | B13: =SUM(C13:O13) -> 60 | C13: 60
... A23: 22 | B23: =SUM(C23:O23) -> 60 | C23: 60
A24: 23 | B24: =SUM(C24:O24) -> 60 | D24: 60
A25: 24 | B25: =SUM(C25:O25) -> 60 | D25: 60
A26: 25 | B26: =SUM(C26:O26) -> 60 | D26: 60
A27: 26 | B27: =SUM(C27:O27) -> 60 | D27: 60
A28: 27 | B28: =SUM(C28:O28) -> 60 | D28: 60
A29: 28 | B29: =SUM(C29:O29) -> 60 | D29: 60
A30: 29 | B30: =SUM(C30:O30) -> 60 | D30: 60
A31: =A30+1 -> 30 | B31: =SUM(C31:O31) -> 60 | D31: 60
A32: =A31+1 -> 31 | B32: =SUM(C32:O32) -> 60 | D32: 60
A33: =A32+1 -> 32 | B33: =SUM(C33:O33) -> 60 | D33: 60
A34: =A33+1 -> 33 | B34: =SUM(C34:O34) -> 60 | D34: 60
A35: =A34+1 -> 34 | B35: =SUM(C35:O35) -> 60 | D35: 60
A36: =A35+1 -> 35 | B36: =SUM(C36:O36) -> 60 | D36: 60
A37: =A36+1 -> 36 | B37: =SUM(C37:O37) -> 60 | D37: 60
A38: =A37+1 -> 37 | B38: =SUM(C38:O38) -> 60 | D38: 60
A39: =A38+1 -> 38 | B39: =SUM(C39:O39) -> 60 | D39: 60
A40: =A39+1 -> 39 | B40: =SUM(C40:O40) -> 60 | D40: 60
A41: =A40+1 -> 40 | B41: =SUM(C41:O41) -> 60 | D41: 60
A42: =A41+1 -> 41 | B42: =SUM(C42:O42) -> 60 | D42: 60
... A46: =A45+1 -> 45 | B46: =SUM(C46:O46) -> 60 | D46: 60
A47: =A46+1 -> 46 | B47: =SUM(C47:O47) -> 60 | E47: 60
A48: =A47+1 -> 47 | B48: =SUM(C48:O48) -> 60 | E48: 60
A49: =A48+1 -> 48 | B49: =SUM(C49:O49) -> 60 | E49: 60
A50: =A49+1 -> 49 | B50: =SUM(C50:O50) -> 60 | F50: 60
A51: =A50+1 -> 50 | B51: =SUM(C51:O51) -> 60 | F51: 60
A52: =A51+1 -> 51 | B52: =SUM(C52:O52) -> 60 | F52: 60
...
